Workbook
Name RoleNames: Helper!$A$1:$A$50
Name RoleNameSource: Helper!$B$1:$AF$50
Name StaffingTable: Table13[#All]
Name StaffingTable: Table1[#All]

Sheet Staffing Plan
A2: Customer
A3: MSX-ID
A4: Date | C4: FY Uplift (%)
A5: Price to Win | C5: Week to start FY uplift
A6: =IF($B$5=0,"No Price to Win",IF($B$7>$B$5,"Over Price To Win by ","Under Price To Win by ")) -> No Price to Win | B6: =IF($B$5=0,"-",$B$7-$B$5) -> - | C6: Sold Margin | D6: =SUMPRODUCT(O20:O69,Q20:Q69) -> 0.21625476 | F6: Delivery Capacity (hrs)
A7: Revenue | B7: =SUMIF(M20:M69,">0") -> 6506840 | C7: Margin Variance (26.7%) | D7: =D6-0.267 -> -0.050745244 | E7: {=Helper3!A2:A6} -> Infrastructure | F7: {=IFERROR(SUM(_xlfn._xlws.FILTER($R$20:$AT$69,$F$20:$F$69=E7)),0)} -> 4856
A8: Cost | B8: =SUMIF(N21:N70,">0") -> 5056635.6 | C8: Governance (% of hours) | D8: ='Staffing Plan'!D19 -> 0.13798403 | E8: AI | F8: {=IFERROR(SUM(_xlfn._xlws.FILTER($R$20:$AT$69,$F$20:$F$69=E8)),0)} -> 6024
C9: Partner Allocation (% of hours) | D9: =SUMIF(G20:I69,"Partner",Q20:Q25) -> 0 | E9: Development | F9: {=IFERROR(SUM(_xlfn._xlws.FILTER($R$20:$AT$69,$F$20:$F$69=E9)),0)} -> 5280
A10: Risk Reserve | B10: =CONCATENATE(TEXT(B15*B7,"$#,##0" )," at ", TEXT('Staffing Plan'!B15,"0%")) -> $0 at 0% | C10: Total Hours | D10: =SUM(I20:I69) -> 25594 | E10: Security | F10: {=IFERROR(SUM(_xlfn._xlws.FILTER($R$20:$AT$69,$F$20:$F$69=E10)),0)} -> 240
A11: T&E | B11: ='Staffing Plan'!B14 -> 0 | C11: Suggested BE Range | D11: =CONCATENATE("Low: $",CEILING(B7,1000)," - High: $",CEILING((B7*1.2),1000)) -> Low: $6507000 - High: $7809000 | E11: ASCM | F11: {=IFERROR(SUM(_xlfn._xlws.FILTER($R$20:$AT$69,$F$20:$F$69=E11)),0)} -> 0
A13: Other Items | C13: Additional Calculators
A14: Travel and Expenses | C14: Governance Calculator: Please run and include a screenshot of the results. | E14: DM Governance Calculator - Power Apps
A15: Risk Reserve (%) | C15: Delivery Compliance, Privacy and Security (DCPS) Estimator: | E15: Compliance Security Estimator
R17: Pre-Init | S17: Sprint 0 | U17: Sprint 1 | W17: Sprint 2 | Y17: Sprint 3 | AA17: Sprint 4 | AC17: Sprint 5
C18: Role | D18: Role Title | E18: Role to Resource Mapping | F18: Role to Functional Area Mapping | G18: Resource Type | H18: Resource Notes and Proposed Individual | I18: Total Hours | J18: List Rate | K18: Bill Rate | L18: Cost Rate | M18: Revenue | N18: Delivery Cost | O18: Sold Margin % | P18: Discount (Premium)% | Q18: Total Allocation % | R18: WK0 | S18: WK1 | T18: WK2 | U18: WK3 | V18: WK4 | W18: WK5 | X18: WK6 | Y18: WK7 | Z18: WK8 | AA18: WK9 | AB18: WK10 | AC18: WK11 | AD18: WK12 | AE18: WK13 | AF18: WK14 | AG18: WK15 | AH18: WK16 | AI18: WK17 | AJ18: WK18 | AK18: WK19 | AL18: WK20 | AM18: WK21 | AN18: WK22 | AO18: WK23 | AP18: WK24 | AQ18: WK25 | AR18: WK26 | AS18: WK27 | AT18: WK28 | AU18: WK29 | AV18: WK30 | AW18: WK31 | AX18: WK32 | AY18: WK33 | AZ18: WK34 | BA18: WK35 | BB18: WK36 | BC18: WK37 | BD18: WK38 | BE18: WK39 | BF18: WK40 | BG18: WK41 | BH18: WK42 | BI18: WK43 | BJ18: WK44 | BK18: WK45
C19: Governance Team | D19: =SUM(Q20:Q25) -> 0.13798403 | M19: {=IF(Table1[[#This Row],[Total Hours]]=0,"-",SUMPRODUCT(Table1[[#This Row],[WK0]:[WK45]], Table1[[#This Row],[Bill Rate]]*IF(COLUMN(Table1[[#This Row],[WK0]:[WK45]])-COLUMN(Table1[[#This Row],[WK0]])>=$D$5, 1+$D$4, 1)))} -> - | N19: {=IF(Table1[[#This Row],[Total Hours]]=0,"-",SUMPRODUCT(Table1[[#This Row],[WK0]:[WK45]], Table1[[#This Row],[Cost Rate]]*IF(COLUMN(Table1[[#This Row],[WK0]:[WK45]])-COLUMN(Table1[[#This Row],[WK0]])>=$D$5, 1+$D$4, 1)))} -> -
C20: DME | D20: Delivery Management Executive | E20: Delivery Management Executive1 | I20: =SUM(R20:BK20) -> 94 | J20: =IFERROR(VLOOKUP(D20,Rates!$A$2:$C$26,3,TRUE),"-") -> 460 | K20: =J20 -> 460 | L20: =IFERROR(VLOOKUP(D20,Rates!$A$2:$C$26,2,TRUE),"-") -> 458.18417 | M20: {=IF(Table1[[#This Row],[Total Hours]]=0,"-",SUMPRODUCT(Table1[[#This Row],[WK0]:[WK45]], Table1[[#This Row],[Bill Rate]]*IF(COLUMN(Table1[[#This Row],[WK0]:[WK45]])-COLUMN(Table1[[#This Row],[WK0]])>=$D$5, 1+$D$4, 1)))} -> 43240 | N20: {=IF(Table1[[#This Row],[Total Hours]]=0,"-",SUMPRODUCT(Table1[[#This Row],[WK0]:[WK45]], Table1[[#This Row],[Cost Rate]]*IF(COLUMN(Table1[[#This Row],[WK0]:[WK45]])-COLUMN(Table1[[#This Row],[WK0]])>=$D$5, 1+$D$4, 1)))} -> 43069.312 | O20: =IFERROR((M20-N20)/M20,"-") -> 0.0039474578 | P20: =IFERROR((J20-K20)/J20,0) -> 0 | Q20: =IFERROR(M20/$B$7,0) -> 0.0066453148 | S20: 4 | T20: 4 | U20: 4 | V20: 4 | W20: 4 | X20: 4 | Y20: 4 | Z20: 2 | AA20: 2 | AB20: 2 | AC20: 2 | AD20: 2 | AE20: 2 | AF20: 2 | AG20: 2 | AH20: 2 | AI20: 2 | AJ20: 2 | AK20: 2 | AL20: 2 | AM20: 2 | AN20: 2 | AO20: 2 | AP20: 2 | AQ20: 2 | AR20: 2 | AS20: 2 | AT20: 2 | AU20: 2 | AV20: 2 | AW20: 2 | AX20: 2 | AY20: 2 | AZ20: 2 | BA20: 2 | BB20: 2 | BC20: 2 | BD20: 2 | BE20: 2 | BF20: 2
C21: Program Architect | D21: Program Architect | E21: Program Architect1 | F21: AI | I21: =SUM(R21:BK21) -> 808 | J21: =IFERROR(VLOOKUP(D21,Rates!$A$2:$C$26,3,TRUE),"-") -> 500 | K21: =J21 -> 500 | L21: =IFERROR(VLOOKUP(D21,Rates!$A$2:$C$26,2,TRUE),"-") -> 461.18447 | M21: {=IF(Table1[[#This Row],[Total Hours]]=0,"-",SUMPRODUCT(Table1[[#This Row],[WK0]:[WK45]], Table1[[#This Row],[Bill Rate]]*IF(COLUMN(Table1[[#This Row],[WK0]:[WK45]])-COLUMN(Table1[[#This Row],[WK0]])>=$D$5, 1+$D$4, 1)))} -> 404000 | N21: {=IF(Table1[[#This Row],[Total Hours]]=0,"-",SUMPRODUCT(Table1[[#This Row],[WK0]:[WK45]], Table1[[#This Row],[Cost Rate]]*IF(COLUMN(Table1[[#This Row],[WK0]:[WK45]])-COLUMN(Table1[[#This Row],[WK0]])>=$D$5, 1+$D$4, 1)))} -> 372637.05 | O21: =IFERROR((M21-N21)/M21,"-") -> 0.077631067 | P21: =IFERROR((J21-K21)/J21,0) -> 0 | Q21: =IFERROR(M21/$B$7,0) -> 0.06208851 | R21: 8 | S21: 20 | T21: 20 | U21: 20 | V21: 20 | W21: 20 | X21: 20 | Y21: 20 | Z21: 20 | AA21: 20 | AB21: 20 | AC21: 20 | AD21: 20 | AE21: 20 | AF21: 20 | AG21: 20 | AH21: 20 | AI21: 20 | AJ21: 20 | AK21: 20 | AL21: 20 | AM21: 20 | AN21: 20 | AO21: 20 | AP21: 20 | AQ21: 20 | AR21: 20 | AS21: 20 | AT21: 20 | AU21: 20 | AV21: 20 | AW21: 20 | AX21: 20 | AY21: 20 | AZ21: 20 | BA21: 20 | BB21: 20 | BC21: 20 | BD21: 20 | BE21: 20 | BF21: 20
C22: Program Manager | D22: Senior Project Manager | E22: Senior Project Manager1 | I22: =SUM(R22:BK22) -> 960 | J22: =IFERROR(VLOOKUP(D22,Rates!$A$2:$C$26,3,TRUE),"-") -> 370 | K22: =J22 -> 370 | L22: =IFERROR(VLOOKUP(D22,Rates!$A$2:$C$26,2,TRUE),"-") -> 258.36679 | M22: {=IF(Table1[[#This Row],[Total Hours]]=0,"-",SUMPRODUCT(Table1[[#This Row],[WK0]:[WK45]], Table1[[#This Row],[Bill Rate]]*IF(COLUMN(Table1[[#This Row],[WK0]:[WK45]])-COLUMN(Table1[[#This Row],[WK0]])>=$D$5, 1+$D$4, 1)))} -> 355200 | N22: {=IF(Table1[[#This Row],[Total Hours]]=0,"-",SUMPRODUCT(Table1[[#This Row],[WK0]:[WK45]], Table1[[#This Row],[Cost Rate]]*IF(COLUMN(Table1[[#This Row],[WK0]:[WK45]])-COLUMN(Table1[[#This Row],[WK0]])>=$D$5, 1+$D$4, 1)))} -> 248032.12 | O22: =IFERROR((M22-N22)/M22,"-") -> 0.30171138 | P22: =IFERROR((J22-K22)/J22,0) -> 0 | Q22: =IFERROR(M22/$B$7,0) -> 0.05458871 | S22: 24 | T22: 24 | U22: 24 | V22: 24 | W22: 24 | X22: 24 | Y22: 24 | Z22: 24 | AA22: 24 | AB22: 24 | AC22: 24 | AD22: 24 | AE22: 24 | AF22: 24 | AG22: 24 | AH22: 24 | AI22: 24 | AJ22: 24 | AK22: 24 | AL22: 24 | AM22: 24 | AN22: 24 | AO22: 24 | AP22: 24 | AQ22: 24 | AR22: 24 | AS22: 24 | AT22: 24 | AU22: 24 | AV22: 24 | AW22: 24 | AX22: 24 | AY22: 24 | AZ22: 24 | BA22: 24 | BB22: 24 | BC22: 24 | BD22: 24 | BE22: 24 | BF22: 24
C23: Scrum Master / Project Manager | D23: GD Offshore | E23: GD Offshore1 | I23: =SUM(R23:BK23) -> 960 | J23: =IFERROR(VLOOKUP(D23,Rates!$A$2:$C$26,3,TRUE),"-") -> 90 | K23: =J23 -> 90 | L23: =IFERROR(VLOOKUP(D23,Rates!$A$2:$C$26,2,TRUE),"-") -> 53.886669 | M23: {=IF(Table1[[#This Row],[Total Hours]]=0,"-",SUMPRODUCT(Table1[[#This Row],[WK0]:[WK45]], Table1[[#This Row],[Bill Rate]]*IF(COLUMN(Table1[[#This Row],[WK0]:[WK45]])-COLUMN(Table1[[#This Row],[WK0]])>=$D$5, 1+$D$4, 1)))} -> 86400 | N23: {=IF(Table1[[#This Row],[Total Hours]]=0,"-",SUMPRODUCT(Table1[[#This Row],[WK0]:[WK45]], Table1[[#This Row],[Cost Rate]]*IF(COLUMN(Table1[[#This Row],[WK0]:[WK45]])-COLUMN(Table1[[#This Row],[WK0]])>=$D$5, 1+$D$4, 1)))} -> 51731.202 | O23: =IFERROR((M23-N23)/M23,"-") -> 0.40125923 | P23: =IFERROR((J23-K23)/J23,0) -> 0 | Q23: =IFERROR(M23/$B$7,0) -> 0.013278335 | S23: 24 | T23: 24 | U23: 24 | V23: 24 | W23: 24 | X23: 24 | Y23: 24 | Z23: 24 | AA23: 24 | AB23: 24 | AC23: 24 | AD23: 24 | AE23: 24 | AF23: 24 | AG23: 24 | AH23: 24 | AI23: 24 | AJ23: 24 | AK23: 24 | AL23: 24 | AM23: 24 | AN23: 24 | AO23: 24 | AP23: 24 | AQ23: 24 | AR23: 24 | AS23: 24 | AT23: 24 | AU23: 24 | AV23: 24 | AW23: 24 | AX23: 24 | AY23: 24 | AZ23: 24 | BA23: 24 | BB23: 24 | BC23: 24 | BD23: 24 | BE23: 24 | BF23: 24
C24: TQA | D24: GD Offshore | E24: GD Offshore2 | I24: =SUM(R24:BK24) -> 100 | J24: =IFERROR(VLOOKUP(D24,Rates!$A$2:$C$26,3,TRUE),"-") -> 90 | K24: =J24 -> 90 | L24: =IFERROR(VLOOKUP(D24,Rates!$A$2:$C$26,2,TRUE),"-") -> 53.886669 | M24: {=IF(Table1[[#This Row],[Total Hours]]=0,"-",SUMPRODUCT(Table1[[#This Row],[WK0]:[WK45]], Table1[[#This Row],[Bill Rate]]*IF(COLUMN(Table1[[#This Row],[WK0]:[WK45]])-COLUMN(Table1[[#This Row],[WK0]])>=$D$5, 1+$D$4, 1)))} -> 9000 | N24: {=IF(Table1[[#This Row],[Total Hours]]=0,"-",SUMPRODUCT(Table1[[#This Row],[WK0]:[WK45]], Table1[[#This Row],[Cost Rate]]*IF(COLUMN(Table1[[#This Row],[WK0]:[WK45]])-COLUMN(Table1[[#This Row],[WK0]])>=$D$5, 1+$D$4, 1)))} -> 5388.6669 | O24: =IFERROR((M24-N24)/M24,"-") -> 0.40125923 | P24: =IFERROR((J24-K24)/J24,0) -> 0 | Q24: =IFERROR(M24/$B$7,0) -> 0.0013831599 | S24: 4 | T24: 4 | U24: 4 | V24: 4 | W24: 4 | X24: 4 | Y24: 4 | Z24: 4 | AA24: 4 | AB24: 4 | AC24: 2 | AD24: 2 | AE24: 2 | AF24: 2 | AG24: 2 | AH24: 2 | AI24: 2 | AJ24: 2 | AK24: 2 | AL24: 2 | AM24: 2 | AN24: 2 | AO24: 2 | AP24: 2 | AQ24: 2 | AR24: 2 | AS24: 2 | AT24: 2 | AU24: 2 | AV24: 2 | AW24: 2 | AX24: 2 | AY24: 2 | AZ24: 2 | BA24: 2 | BB24: 2 | BC24: 2 | BD24: 2 | BE24: 2 | BF24: 2
I25: =SUM(R25:BK25) -> 0 | J25: =IFERROR(VLOOKUP(D25,Rates!$A$2:$C$26,3,TRUE),"-") -> - | K25: =J25 -> - | L25: =IFERROR(VLOOKUP(D25,Rates!$A$2:$C$26,2,TRUE),"-") -> - | M25: {=IF(Table1[[#This Row],[Total Hours]]=0,"-",SUMPRODUCT(Table1[[#This Row],[WK0]:[WK45]], Table1[[#This Row],[Bill Rate]]*IF(COLUMN(Table1[[#This Row],[WK0]:[WK45]])-COLUMN(Table1[[#This Row],[WK0]])>=$D$5, 1+$D$4, 1)))} -> - | N25: {=IF(Table1[[#This Row],[Total Hours]]=0,"-",SUMPRODUCT(Table1[[#This Row],[WK0]:[WK45]], Table1[[#This Row],[Cost Rate]]*IF(COLUMN(Table1[[#This Row],[WK0]:[WK45]])-COLUMN(Table1[[#This Row],[WK0]])>=$D$5, 1+$D$4, 1)))} -> - | O25: =IFERROR((M25-N25)/M25,"-") -> - | P25: =IFERROR((J25-K25)/J25,0) -> 0 | Q25: =IFERROR(M25/$B$7,0) -> 0
D26: =SUM(Q27:Q27) -> 0 | M26: {=IF(Table1[[#This Row],[Total Hours]]=0,"-",SUMPRODUCT(Table1[[#This Row],[WK0]:[WK45]], Table1[[#This Row],[Bill Rate]]*IF(COLUMN(Table1[[#This Row],[WK0]:[WK45]])-COLUMN(Table1[[#This Row],[WK0]])>=$D$5, 1+$D$4, 1)))} -> - | N26: {=IF(Table1[[#This Row],[Total Hours]]=0,"-",SUMPRODUCT(Table1[[#This Row],[WK0]:[WK45]], Table1[[#This Row],[Cost Rate]]*IF(COLUMN(Table1[[#This Row],[WK0]:[WK45]])-COLUMN(Table1[[#This Row],[WK0]])>=$D$5, 1+$D$4, 1)))} -> -
I27: =SUM(R27:AT27) -> 0 | J27: =IFERROR(VLOOKUP(D27,Rates!$A$2:$C$26,3,TRUE),"-") -> - | K27: =J27 -> - | L27: =IFERROR(VLOOKUP(D27,Rates!$A$2:$C$26,2,TRUE),"-") -> - | M27: {=IF(Table1[[#This Row],[Total Hours]]=0,"-",SUMPRODUCT(Table1[[#This Row],[WK0]:[WK45]], Table1[[#This Row],[Bill Rate]]*IF(COLUMN(Table1[[#This Row],[WK0]:[WK45]])-COLUMN(Table1[[#This Row],[WK0]])>=$D$5, 1+$D$4, 1)))} -> - | N27: {=IF(Table1[[#This Row],[Total Hours]]=0,"-",SUMPRODUCT(Table1[[#This Row],[WK0]:[WK45]], Table1[[#This Row],[Cost Rate]]*IF(COLUMN(Table1[[#This Row],[WK0]:[WK45]])-COLUMN(Table1[[#This Row],[WK0]])>=$D$5, 1+$D$4, 1)))} -> - | O27: =IFERROR((M27-N27)/M27,"-") -> - | P27: =IFERROR((J27-K27)/J27,0) -> 0 | Q27: =IFERROR(M27/$B$7,0) -> 0
C28: AI Landing Zone / Infra | D28: =SUM(Q29:Q34) -> 0.25530672 | M28: {=IF(Table1[[#This Row],[Total Hours]]=0,"-",SUMPRODUCT(Table1[[#This Row],[WK0]:[WK45]], Table1[[#This Row],[Bill Rate]]*IF(COLUMN(Table1[[#This Row],[WK0]:[WK45]])-COLUMN(Table1[[#This Row],[WK0]])>=$D$5, 1+$D$4, 1)))} -> - | N28: {=IF(Table1[[#This Row],[Total Hours]]=0,"-",SUMPRODUCT(Table1[[#This Row],[WK0]:[WK45]], Table1[[#This Row],[Cost Rate]]*IF(COLUMN(Table1[[#This Row],[WK0]:[WK45]])-COLUMN(Table1[[#This Row],[WK0]])>=$D$5, 1+$D$4, 1)))} -> -
C29: App/ Infra Architect | D29: Senior Domain Solution Architect | E29: Senior Domain Solution Architect1 | F29: AI | H29: Azure Infra/Landing Zone | I29: =SUM(R29:BK29) -> 1208 | J29: =IFERROR(VLOOKUP(D29,Rates!$A$2:$C$26,3,TRUE),"-") -> 490 | K29: =J29 -> 490 | L29: =IFERROR(VLOOKUP(D29,Rates!$A$2:$C$26,2,TRUE),"-") -> 404.15452 | M29: {=IF(Table1[[#This Row],[Total Hours]]=0,"-",SUMPRODUCT(Table1[[#This Row],[WK0]:[WK45]], Table1[[#This Row],[Bill Rate]]*IF(COLUMN(Table1[[#This Row],[WK0]:[WK45]])-COLUMN(Table1[[#This Row],[WK0]])>=$D$5, 1+$D$4, 1)))} -> 591920 | N29: {=IF(Table1[[#This Row],[Total Hours]]=0,"-",SUMPRODUCT(Table1[[#This Row],[WK0]:[WK45]], Table1[[#This Row],[Cost Rate]]*IF(COLUMN(Table1[[#This Row],[WK0]:[WK45]])-COLUMN(Table1[[#This Row],[WK0]])>=$D$5, 1+$D$4, 1)))} -> 488218.66 | O29: =IFERROR((M29-N29)/M29,"-") -> 0.17519486 | P29: =IFERROR((J29-K29)/J29,0) -> 0 | Q29: =IFERROR(M29/$B$7,0) -> 0.090968888 | R29: 8 | S29: 30 | T29: 30 | U29: 30 | V29: 30 | W29: 30 | X29: 30 | Y29: 30 | Z29: 30 | AA29: 30 | AB29: 30 | AC29: 30 | AD29: 30 | AE29: 30 | AF29: 30 | AG29: 30 | AH29: 30 | AI29: 30 | AJ29: 30 | AK29: 30 | AL29: 30 | AM29: 30 | AN29: 30 | AO29: 30 | AP29: 30 | AQ29: 30 | AR29: 30 | AS29: 30 | AT29: 30 | AU29: 30 | AV29: 30 | AW29: 30 | AX29: 30 | AY29: 30 | AZ29: 30 | BA29: 30 | BB29: 30 | BC29: 30 | BD29: 30 | BE29: 30 | BF29: 30
C30: Sr. Consultant (Infra) | D30: Senior Consultant | E30: Senior Consultant1 | F30: Infrastructure | H30: Azure Infra/Landing Zone | I30: =SUM(R30:BK30) -> 1608 | J30: =IFERROR(VLOOKUP(D30,Rates!$A$2:$C$26,3,TRUE),"-") -> 365 | K30: =J30 -> 365 | L30: =IFERROR(VLOOKUP(D30,Rates!$A$2:$C$26,2,TRUE),"-") -> 256.15021 | M30: {=IF(Table1[[#This Row],[Total Hours]]=0,"-",SUMPRODUCT(Table1[[#This Row],[WK0]:[WK45]], Table1[[#This Row],[Bill Rate]]*IF(COLUMN(Table1[[#This Row],[WK0]:[WK45]])-COLUMN(Table1[[#This Row],[WK0]])>=$D$5, 1+$D$4, 1)))} -> 586920 | N30: {=IF(Table1[[#This Row],[Total Hours]]=0,"-",SUMPRODUCT(Table1[[#This Row],[WK0]:[WK45]], Table1[[#This Row],[Cost Rate]]*IF(COLUMN(Table1[[#This Row],[WK0]:[WK45]])-COLUMN(Table1[[#This Row],[WK0]])>=$D$5, 1+$D$4, 1)))} -> 411889.54 | O30: =IFERROR((M30-N30)/M30,"-") -> 0.2982186 | P30: =IFERROR((J30-K30)/J30,0) -> 0 | Q30: =IFERROR(M30/$B$7,0) -> 0.090200466 | R30: 8 | S30: 40 | T30: 40 | U30: 40 | V30: 40 | W30: 40 | X30: 40 | Y30: 40 | Z30: 40 | AA30: 40 | AB30: 40 | AC30: 40 | AD30: 40 | AE30: 40 | AF30: 40 | AG30: 40 | AH30: 40 | AI30: 40 | AJ30: 40 | AK30: 40 | AL30: 40 | AM30: 40 | AN30: 40 | AO30: 40 | AP30: 40 | AQ30: 40 | AR30: 40 | AS30: 40 | AT30: 40 | AU30: 40 | AV30: 40 | AW30: 40 | AX30: 40 | AY30: 40 | AZ30: 40 | BA30: 40 | BB30: 40 | BC30: 40 | BD30: 40 | BE30: 40 | BF30: 40
C31: App/ Infra Consultant | D31: GD Offshore | E31: GD Offshore1 | F31: Infrastructure | H31: Azure Infra/Landing Zone | I31: =SUM(R31:BK31) -> 1600 | J31: =IFERROR(VLOOKUP(D31,Rates!$A$2:$C$26,3,TRUE),"-") -> 90 | K31: =J31 -> 90 | L31: =IFERROR(VLOOKUP(D31,Rates!$A$2:$C$26,2,TRUE),"-") -> 53.886669 | M31: {=IF(Table1[[#This Row],[Total Hours]]=0,"-",SUMPRODUCT(Table1[[#This Row],[WK0]:[WK45]], Table1[[#This Row],[Bill Rate]]*IF(COLUMN(Table1[[#This Row],[WK0]:[WK45]])-COLUMN(Table1[[#This Row],[WK0]])>=$D$5, 1+$D$4, 1)))} -> 144000 | N31: {=IF(Table1[[#This Row],[Total Hours]]=0,"-",SUMPRODUCT(Table1[[#This Row],[WK0]:[WK45]], Table1[[#This Row],[Cost Rate]]*IF(COLUMN(Table1[[#This Row],[WK0]:[WK45]])-COLUMN(Table1[[#This Row],[WK0]])>=$D$5, 1+$D$4, 1)))} -> 86218.671 | O31: =IFERROR((M31-N31)/M31,"-") -> 0.40125923 | P31: =IFERROR((J31-K31)/J31,0) -> 0 | Q31: =IFERROR(M31/$B$7,0) -> 0.022130558 | S31: 40 | T31: 40 | U31: 40 | V31: 40 | W31: 40 | X31: 40 | Y31: 40 | Z31: 40 | AA31: 40 | AB31: 40 | AC31: 40 | AD31: 40 | AE31: 40 | AF31: 40 | AG31: 40 | AH31: 40 | AI31: 40 | AJ31: 40 | AK31: 40 | AL31: 40 | AM31: 40 | AN31: 40 | AO31: 40 | AP31: 40 | AQ31: 40 | AR31: 40 | AS31: 40 | AT31: 40 | AU31: 40 | AV31: 40 | AW31: 40 | AX31: 40 | AY31: 40 | AZ31: 40 | BA31: 40 | BB31: 40 | BC31: 40 | BD31: 40 | BE31: 40 | BF31: 40
C32: DevOps Consultant | D32: GD Offshore | E32: GD Offshore2 | F32: Infrastructure | H32: Intune | I32: =SUM(R32:BK32) -> 1560 | J32: =IFERROR(VLOOKUP(D32,Rates!$A$2:$C$26,3,TRUE),"-") -> 90 | K32: =J32 -> 90 | L32: =IFERROR(VLOOKUP(D32,Rates!$A$2:$C$26,2,TRUE),"-") -> 53.886669 | M32: {=IF(Table1[[#This Row],[Total Hours]]=0,"-",SUMPRODUCT(Table1[[#This Row],[WK0]:[WK45]], Table1[[#This Row],[Bill Rate]]*IF(COLUMN(Table1[[#This Row],[WK0]:[WK45]])-COLUMN(Table1[[#This Row],[WK0]])>=$D$5, 1+$D$4, 1)))} -> 140400 | N32: {=IF(Table1[[#This Row],[Total Hours]]=0,"-",SUMPRODUCT(Table1[[#This Row],[WK0]:[WK45]], Table1[[#This Row],[Cost Rate]]*IF(COLUMN(Table1[[#This Row],[WK0]:[WK45]])-COLUMN(Table1[[#This Row],[WK0]])>=$D$5, 1+$D$4, 1)))} -> 84063.204 | O32: =IFERROR((M32-N32)/M32,"-") -> 0.40125923 | P32: =IFERROR((J32-K32)/J32,0) -> 0 | Q32: =IFERROR(M32/$B$7,0) -> 0.021577294 | S32: 20 | T32: 20 | U32: 40 | V32: 40 | W32: 40 | X32: 40 | Y32: 40 | Z32: 40 | AA32: 40 | AB32: 40 | AC32: 40 | AD32: 40 | AE32: 40 | AF32: 40 | AG32: 40 | AH32: 40 | AI32: 40 | AJ32: 40 | AK32: 40 | AL32: 40 | AM32: 40 | AN32: 40 | AO32: 40 | AP32: 40 | AQ32: 40 | AR32: 40 | AS32: 40 | AT32: 40 | AU32: 40 | AV32: 40 | AW32: 40 | AX32: 40 | AY32: 40 | AZ32: 40 | BA32: 40 | BB32: 40 | BC32: 40 | BD32: 40 | BE32: 40 | BF32: 40
C33: DevOps Consultant | D33: GD Offshore | E33: GD Offshore3 | F33: Infrastructure | H33: Intune | I33: =SUM(R33:BK33) -> 1560 | J33: =IFERROR(VLOOKUP(D33,Rates!$A$2:$C$26,3,TRUE),"-") -> 90 | K33: =J33 -> 90 | L33: =IFERROR(VLOOKUP(D33,Rates!$A$2:$C$26,2,TRUE),"-") -> 53.886669 | M33: {=IF(Table1[[#This Row],[Total Hours]]=0,"-",SUMPRODUCT(Table1[[#This Row],[WK0]:[WK45]], Table1[[#This Row],[Bill Rate]]*IF(COLUMN(Table1[[#This Row],[WK0]:[WK45]])-COLUMN(Table1[[#This Row],[WK0]])>=$D$5, 1+$D$4, 1)))} -> 140400 | N33: {=IF(Table1[[#This Row],[Total Hours]]=0,"-",SUMPRODUCT(Table1[[#This Row],[WK0]:[WK45]], Table1[[#This Row],[Cost Rate]]*IF(COLUMN(Table1[[#This Row],[WK0]:[WK45]])-COLUMN(Table1[[#This Row],[WK0]])>=$D$5, 1+$D$4, 1)))} -> 84063.204 | O33: =IFERROR((M33-N33)/M33,"-") -> 0.40125923 | P33: =IFERROR((J33-K33)/J33,0) -> 0 | Q33: =IFERROR(M33/$B$7,0) -> 0.021577294 | S33: 20 | T33: 20 | U33: 40 | V33: 40 | W33: 40 | X33: 40 | Y33: 40 | Z33: 40 | AA33: 40 | AB33: 40 | AC33: 40 | AD33: 40 | AE33: 40 | AF33: 40 | AG33: 40 | AH33: 40 | AI33: 40 | AJ33: 40 | AK33: 40 | AL33: 40 | AM33: 40 | AN33: 40 | AO33: 40 | AP33: 40 | AQ33: 40 | AR33: 40 | AS33: 40 | AT33: 40 | AU33: 40 | AV33: 40 | AW33: 40 | AX33: 40 | AY33: 40 | AZ33: 40 | BA33: 40 | BB33: 40 | BC33: 40 | BD33: 40 | BE33: 40 | BF33: 40
C34: Security Consultant | D34: GD Offshore | E34: Senior Consultant2 | F34: Infrastructure | H34: Intune | I34: =SUM(R34:BK34) -> 640 | J34: =IFERROR(VLOOKUP(D34,Rates!$A$2:$C$26,3,TRUE),"-") -> 90 | K34: =J34 -> 90 | L34: =IFERROR(VLOOKUP(D34,Rates!$A$2:$C$26,2,TRUE),"-") -> 53.886669 | M34: {=IF(Table1[[#This Row],[Total Hours]]=0,"-",SUMPRODUCT(Table1[[#This Row],[WK0]:[WK45]], Table1[[#This Row],[Bill Rate]]*IF(COLUMN(Table1[[#This Row],[WK0]:[WK45]])-COLUMN(Table1[[#This Row],[WK0]])>=$D$5, 1+$D$4, 1)))} -> 57600 | N34: {=IF(Table1[[#This Row],[Total Hours]]=0,"-",SUMPRODUCT(Table1[[#This Row],[WK0]:[WK45]], Table1[[#This Row],[Cost Rate]]*IF(COLUMN(Table1[[#This Row],[WK0]:[WK45]])-COLUMN(Table1[[#This Row],[WK0]])>=$D$5, 1+$D$4, 1)))} -> 34487.468 | O34: =IFERROR((M34-N34)/M34,"-") -> 0.40125923 | P34: =IFERROR((J34-K34)/J34,0) -> 0 | Q34: =IFERROR(M34/$B$7,0) -> 0.0088522232 | S34: 16 | T34: 16 | U34: 16 | V34: 16 | W34: 16 | X34: 16 | Y34: 16 | Z34: 16 | AA34: 16 | AB34: 16 | AC34: 16 | AD34: 16 | AE34: 16 | AF34: 16 | AG34: 16 | AH34: 16 | AI34: 16 | AJ34: 16 | AK34: 16 | AL34: 16 | AM34: 16 | AN34: 16 | AO34: 16 | AP34: 16 | AQ34: 16 | AR34: 16 | AS34: 16 | AT34: 16 | AU34: 16 | AV34: 16 | AW34: 16 | AX34: 16 | AY34: 16 | AZ34: 16 | BA34: 16 | BB34: 16 | BC34: 16 | BD34: 16 | BE34: 16 | BF34: 16
E35: Senior Domain Soultion Architect2 | F35: Security | H35: Intune | I35: =SUM(R35:BK35) -> 0 | J35: =IFERROR(VLOOKUP(D35,Rates!$A$2:$C$26,3,TRUE),"-") -> - | K35: =J35 -> - | L35: =IFERROR(VLOOKUP(D35,Rates!$A$2:$C$26,2,TRUE),"-") -> - | M35: {=IF(Table1[[#This Row],[Total Hours]]=0,"-",SUMPRODUCT(Table1[[#This Row],[WK0]:[WK45]], Table1[[#This Row],[Bill Rate]]*IF(COLUMN(Table1[[#This Row],[WK0]:[WK45]])-COLUMN(Table1[[#This Row],[WK0]])>=$D$5, 1+$D$4, 1)))} -> - | N35: {=IF(Table1[[#This Row],[Total Hours]]=0,"-",SUMPRODUCT(Table1[[#This Row],[WK0]:[WK45]], Table1[[#This Row],[Cost Rate]]*IF(COLUMN(Table1[[#This Row],[WK0]:[WK45]])-COLUMN(Table1[[#This Row],[WK0]])>=$D$5, 1+$D$4, 1)))} -> - | O35: =IFERROR((M35-N35)/M35,"-") -> - | P35: =IFERROR((J35-K35)/J35,0) -> 0 | Q35: =IFERROR(M35/$B$7,0) -> 0
C36: In Vehicle (Edge) - Agentic Solution -AI SLM, Model Tuning | D36: =SUM(Q37:Q41) -> 0.40683342 | M36: {=IF(Table1[[#This Row],[Total Hours]]=0,"-",SUMPRODUCT(Table1[[#This Row],[WK0]:[WK45]], Table1[[#This Row],[Bill Rate]]*IF(COLUMN(Table1[[#This Row],[WK0]:[WK45]])-COLUMN(Table1[[#This Row],[WK0]])>=$D$5, 1+$D$4, 1)))} -> - | N36: {=IF(Table1[[#This Row],[Total Hours]]=0,"-",SUMPRODUCT(Table1[[#This Row],[WK0]:[WK45]], Table1[[#This Row],[Cost Rate]]*IF(COLUMN(Table1[[#This Row],[WK0]:[WK45]])-COLUMN(Table1[[#This Row],[WK0]])>=$D$5, 1+$D$4, 1)))} -> -
C37: Prin Data Scientist | D37: Principal Data Scientist | E37: Principal Data Scientist1 | F37: AI | H37: Language Model training and fine tunning | I37: =SUM(R37:BK37) -> 808 | J37: =IFERROR(VLOOKUP(D37,Rates!$A$2:$C$26,3,TRUE),"-") -> 500 | K37: =J37 -> 500 | L37: =IFERROR(VLOOKUP(D37,Rates!$A$2:$C$26,2,TRUE),"-") -> 367.31087 | M37: {=IF(Table1[[#This Row],[Total Hours]]=0,"-",SUMPRODUCT(Table1[[#This Row],[WK0]:[WK45]], Table1[[#This Row],[Bill Rate]]*IF(COLUMN(Table1[[#This Row],[WK0]:[WK45]])-COLUMN(Table1[[#This Row],[WK0]])>=$D$5, 1+$D$4, 1)))} -> 404000 | N37: {=IF(Table1[[#This Row],[Total Hours]]=0,"-",SUMPRODUCT(Table1[[#This Row],[WK0]:[WK45]], Table1[[#This Row],[Cost Rate]]*IF(COLUMN(Table1[[#This Row],[WK0]:[WK45]])-COLUMN(Table1[[#This Row],[WK0]])>=$D$5, 1+$D$4, 1)))} -> 296787.19 | O37: =IFERROR((M37-N37)/M37,"-") -> 0.26537825 | P37: =IFERROR((J37-K37)/J37,0) -> 0 | Q37: =IFERROR(M37/$B$7,0) -> 0.06208851 | R37: 8 | S37: 20 | T37: 20 | U37: 20 | V37: 20 | W37: 20 | X37: 20 | Y37: 20 | Z37: 20 | AA37: 20 | AB37: 20 | AC37: 20 | AD37: 20 | AE37: 20 | AF37: 20 | AG37: 20 | AH37: 20 | AI37: 20 | AJ37: 20 | AK37: 20 | AL37: 20 | AM37: 20 | AN37: 20 | AO37: 20 | AP37: 20 | AQ37: 20 | AR37: 20 | AS37: 20 | AT37: 20 | AU37: 20 | AV37: 20 | AW37: 20 | AX37: 20 | AY37: 20 | AZ37: 20 | BA37: 20 | BB37: 20 | BC37: 20 | BD37: 20 | BE37: 20 | BF37: 20
C38: Sr. Data Scientist | D38: Data Scientist | E38: Data Scientist1 | F38: AI | H38: Speech To Text Model training and fine tunning | I38: =SUM(R38:BK38) -> 808 | J38: =IFERROR(VLOOKUP(D38,Rates!$A$2:$C$26,3,TRUE),"-") -> 400 | K38: =J38 -> 400 | L38: =IFERROR(VLOOKUP(D38,Rates!$A$2:$C$26,2,TRUE),"-") -> 360.62809 | M38: {=IF(Table1[[#This Row],[Total Hours]]=0,"-",SUMPRODUCT(Table1[[#This Row],[WK0]:[WK45]], Table1[[#This Row],[Bill Rate]]*IF(COLUMN(Table1[[#This Row],[WK0]:[WK45]])-COLUMN(Table1[[#This Row],[WK0]])>=$D$5, 1+$D$4, 1)))} -> 323200 | N38: {=IF(Table1[[#This Row],[Total Hours]]=0,"-",SUMPRODUCT(Table1[[#This Row],[WK0]:[WK45]], Table1[[#This Row],[Cost Rate]]*IF(COLUMN(Table1[[#This Row],[WK0]:[WK45]])-COLUMN(Table1[[#This Row],[WK0]])>=$D$5, 1+$D$4, 1)))} -> 291387.5 | O38: =IFERROR((M38-N38)/M38,"-") -> 0.098429763 | P38: =IFERROR((J38-K38)/J38,0) -> 0 | Q38: =IFERROR(M38/$B$7,0) -> 0.049670808 | R38: 8 | S38: 20 | T38: 20 | U38: 20 | V38: 20 | W38: 20 | X38: 20 | Y38: 20 | Z38: 20 | AA38: 20 | AB38: 20 | AC38: 20 | AD38: 20 | AE38: 20 | AF38: 20 | AG38: 20 | AH38: 20 | AI38: 20 | AJ38: 20 | AK38: 20 | AL38: 20 | AM38: 20 | AN38: 20 | AO38: 20 | AP38: 20 | AQ38: 20 | AR38: 20 | AS38: 20 | AT38: 20 | AU38: 20 | AV38: 20 | AW38: 20 | AX38: 20 | AY38: 20 | AZ38: 20 | BA38: 20 | BB38: 20 | BC38: 20 | BD38: 20 | BE38: 20 | BF38: 20
C39: Sr. Data Scientist | D39: Data Scientist | E39: Data Scientist2 | F39: AI | H39: Speech To Speech Model training and fine tunning | I39: =SUM(R39:BK39) -> 1600 | J39: =IFERROR(VLOOKUP(D39,Rates!$A$2:$C$26,3,TRUE),"-") -> 400 | K39: =J39 -> 400 | L39: =IFERROR(VLOOKUP(D39,Rates!$A$2:$C$26,2,TRUE),"-") -> 360.62809 | M39: {=IF(Table1[[#This Row],[Total Hours]]=0,"-",SUMPRODUCT(Table1[[#This Row],[WK0]:[WK45]], Table1[[#This Row],[Bill Rate]]*IF(COLUMN(Table1[[#This Row],[WK0]:[WK45]])-COLUMN(Table1[[#This Row],[WK0]])>=$D$5, 1+$D$4, 1)))} -> 640000 | N39: {=IF(Table1[[#This Row],[Total Hours]]=0,"-",SUMPRODUCT(Table1[[#This Row],[WK0]:[WK45]], Table1[[#This Row],[Cost Rate]]*IF(COLUMN(Table1[[#This Row],[WK0]:[WK45]])-COLUMN(Table1[[#This Row],[WK0]])>=$D$5, 1+$D$4, 1)))} -> 577004.95 | O39: =IFERROR((M39-N39)/M39,"-") -> 0.098429763 | P39: =IFERROR((J39-K39)/J39,0) -> 0 | Q39: =IFERROR(M39/$B$7,0) -> 0.098358036 | S39: 40 | T39: 40 | U39: 40 | V39: 40 | W39: 40 | X39: 40 | Y39: 40 | Z39: 40 | AA39: 40 | AB39: 40 | AC39: 40 | AD39: 40 | AE39: 40 | AF39: 40 | AG39: 40 | AH39: 40 | AI39: 40 | AJ39: 40 | AK39: 40 | AL39: 40 | AM39: 40 | AN39: 40 | AO39: 40 | AP39: 40 | AQ39: 40 | AR39: 40 | AS39: 40 | AT39: 40 | AU39: 40 | AV39: 40 | AW39: 40 | AX39: 40 | AY39: 40 | AZ39: 40 | BA39: 40 | BB39: 40 | BC39: 40 | BD39: 40 | BE39: 40 | BF39: 40
C40: Sr. Data Scientist | D40: Data Scientist | E40: Data Scientist3 | F40: AI | H40: Text to Speech Model training and fine tuning | I40: =SUM(R40:BK40) -> 1600 | J40: =IFERROR(VLOOKUP(D40,Rates!$A$2:$C$26,3,TRUE),"-") -> 400 | K40: =J40 -> 400 | L40: =IFERROR(VLOOKUP(D40,Rates!$A$2:$C$26,2,TRUE),"-") -> 360.62809 | M40: {=IF(Table1[[#This Row],[Total Hours]]=0,"-",SUMPRODUCT(Table1[[#This Row],[WK0]:[WK45]], Table1[[#This Row],[Bill Rate]]*IF(COLUMN(Table1[[#This Row],[WK0]:[WK45]])-COLUMN(Table1[[#This Row],[WK0]])>=$D$5, 1+$D$4, 1)))} -> 640000 | N40: {=IF(Table1[[#This Row],[Total Hours]]=0,"-",SUMPRODUCT(Table1[[#This Row],[WK0]:[WK45]], Table1[[#This Row],[Cost Rate]]*IF(COLUMN(Table1[[#This Row],[WK0]:[WK45]])-COLUMN(Table1[[#This Row],[WK0]])>=$D$5, 1+$D$4, 1)))} -> 577004.95 | O40: =IFERROR((M40-N40)/M40,"-") -> 0.098429763 | P40: =IFERROR((J40-K40)/J40,0) -> 0 | Q40: =IFERROR(M40/$B$7,0) -> 0.098358036 | S40: 40 | T40: 40 | U40: 40 | V40: 40 | W40: 40 | X40: 40 | Y40: 40 | Z40: 40 | AA40: 40 | AB40: 40 | AC40: 40 | AD40: 40 | AE40: 40 | AF40: 40 | AG40: 40 | AH40: 40 | AI40: 40 | AJ40: 40 | AK40: 40 | AL40: 40 | AM40: 40 | AN40: 40 | AO40: 40 | AP40: 40 | AQ40: 40 | AR40: 40 | AS40: 40 | AT40: 40 | AU40: 40 | AV40: 40 | AW40: 40 | AX40: 40 | AY40: 40 | AZ40: 40 | BA40: 40 | BB40: 40 | BC40: 40 | BD40: 40 | BE40: 40 | BF40: 40
C41: Sr. Data Scientist | D41: Data Scientist | E41: Data Scientist4 | F41: AI | H41: Wakeup word/VAD training and fine tuning | I41: =SUM(R41:BK41) -> 1600 | J41: =IFERROR(VLOOKUP(D41,Rates!$A$2:$C$26,3,TRUE),"-") -> 400 | K41: =J41 -> 400 | L41: =IFERROR(VLOOKUP(D41,Rates!$A$2:$C$26,2,TRUE),"-") -> 360.62809 | M41: {=IF(Table1[[#This Row],[Total Hours]]=0,"-",SUMPRODUCT(Table1[[#This Row],[WK0]:[WK45]], Table1[[#This Row],[Bill Rate]]*IF(COLUMN(Table1[[#This Row],[WK0]:[WK45]])-COLUMN(Table1[[#This Row],[WK0]])>=$D$5, 1+$D$4, 1)))} -> 640000 | N41: {=IF(Table1[[#This Row],[Total Hours]]=0,"-",SUMPRODUCT(Table1[[#This Row],[WK0]:[WK45]], Table1[[#This Row],[Cost Rate]]*IF(COLUMN(Table1[[#This Row],[WK0]:[WK45]])-COLUMN(Table1[[#This Row],[WK0]])>=$D$5, 1+$D$4, 1)))} -> 577004.95 | O41: =IFERROR((M41-N41)/M41,"-") -> 0.098429763 | P41: =IFERROR((J41-K41)/J41,0) -> 0 | Q41: =IFERROR(M41/$B$7,0) -> 0.098358036 | S41: 40 | T41: 40 | U41: 40 | V41: 40 | W41: 40 | X41: 40 | Y41: 40 | Z41: 40 | AA41: 40 | AB41: 40 | AC41: 40 | AD41: 40 | AE41: 40 | AF41: 40 | AG41: 40 | AH41: 40 | AI41: 40 | AJ41: 40 | AK41: 40 | AL41: 40 | AM41: 40 | AN41: 40 | AO41: 40 | AP41: 40 | AQ41: 40 | AR41: 40 | AS41: 40 | AT41: 40 | AU41: 40 | AV41: 40 | AW41: 40 | AX41: 40 | AY41: 40 | AZ41: 40 | BA41: 40 | BB41: 40 | BC41: 40 | BD41: 40 | BE41: 40 | BF41: 40
C42: Sr. Consultant | D42: Senior Consultant | E42: Senior Consultant1 | F42: Development | H42: Car Integration, Dev Lead | I42: =SUM(R42:BK42) -> 800 | J42: =IFERROR(VLOOKUP(D42,Rates!$A$2:$C$26,3,TRUE),"-") -> 365 | K42: =J42 -> 365 | L42: =IFERROR(VLOOKUP(D42,Rates!$A$2:$C$26,2,TRUE),"-") -> 256.15021 | M42: {=IF(Table1[[#This Row],[Total Hours]]=0,"-",SUMPRODUCT(Table1[[#This Row],[WK0]:[WK45]], Table1[[#This Row],[Bill Rate]]*IF(COLUMN(Table1[[#This Row],[WK0]:[WK45]])-COLUMN(Table1[[#This Row],[WK0]])>=$D$5, 1+$D$4, 1)))} -> 292000 | N42: {=IF(Table1[[#This Row],[Total Hours]]=0,"-",SUMPRODUCT(Table1[[#This Row],[WK0]:[WK45]], Table1[[#This Row],[Cost Rate]]*IF(COLUMN(Table1[[#This Row],[WK0]:[WK45]])-COLUMN(Table1[[#This Row],[WK0]])>=$D$5, 1+$D$4, 1)))} -> 204920.17 | O42: =IFERROR((M42-N42)/M42,"-") -> 0.2982186 | P42: =IFERROR((J42-K42)/J42,0) -> 0 | Q42: =IFERROR(M42/$B$7,0) -> 0.044875854 | S42: 20 | T42: 20 | U42: 20 | V42: 20 | W42: 20 | X42: 20 | Y42: 20 | Z42: 20 | AA42: 20 | AB42: 20 | AC42: 20 | AD42: 20 | AE42: 20 | AF42: 20 | AG42: 20 | AH42: 20 | AI42: 20 | AJ42: 20 | AK42: 20 | AL42: 20 | AM42: 20 | AN42: 20 | AO42: 20 | AP42: 20 | AQ42: 20 | AR42: 20 | AS42: 20 | AT42: 20 | AU42: 20 | AV42: 20 | AW42: 20 | AX42: 20 | AY42: 20 | AZ42: 20 | BA42: 20 | BB42: 20 | BC42: 20 | BD42: 20 | BE42: 20 | BF42: 20
C43: Sr. Consultant | D43: Senior Consultant | E43: Senior Consultant2 | F43: Development | H43: DevOps/MLOps, CI/CD | I43: =SUM(R43:BK43) -> 800 | J43: =IFERROR(VLOOKUP(D43,Rates!$A$2:$C$26,3,TRUE),"-") -> 365 | K43: =J43 -> 365 | L43: =IFERROR(VLOOKUP(D43,Rates!$A$2:$C$26,2,TRUE),"-") -> 256.15021 | M43: {=IF(Table1[[#This Row],[Total Hours]]=0,"-",SUMPRODUCT(Table1[[#This Row],[WK0]:[WK45]], Table1[[#This Row],[Bill Rate]]*IF(COLUMN(Table1[[#This Row],[WK0]:[WK45]])-COLUMN(Table1[[#This Row],[WK0]])>=$D$5, 1+$D$4, 1)))} -> 292000 | N43: {=IF(Table1[[#This Row],[Total Hours]]=0,"-",SUMPRODUCT(Table1[[#This Row],[WK0]:[WK45]], Table1[[#This Row],[Cost Rate]]*IF(COLUMN(Table1[[#This Row],[WK0]:[WK45]])-COLUMN(Table1[[#This Row],[WK0]])>=$D$5, 1+$D$4, 1)))} -> 204920.17 | O43: =IFERROR((M43-N43)/M43,"-") -> 0.2982186 | P43: =IFERROR((J43-K43)/J43,0) -> 0 | Q43: =IFERROR(M43/$B$7,0) -> 0.044875854 | S43: 20 | T43: 20 | U43: 20 | V43: 20 | W43: 20 | X43: 20 | Y43: 20 | Z43: 20 | AA43: 20 | AB43: 20 | AC43: 20 | AD43: 20 | AE43: 20 | AF43: 20 | AG43: 20 | AH43: 20 | AI43: 20 | AJ43: 20 | AK43: 20 | AL43: 20 | AM43: 20 | AN43: 20 | AO43: 20 | AP43: 20 | AQ43: 20 | AR43: 20 | AS43: 20 | AT43: 20 | AU43: 20 | AV43: 20 | AW43: 20 | AX43: 20 | AY43: 20 | AZ43: 20 | BA43: 20 | BB43: 20 | BC43: 20 | BD43: 20 | BE43: 20 | BF43: 20
...

Sheet Assumptions
B2: Assumptions for Cloud Hub Infra Estimates
B3: 1. Landing Zone (CAF Enterprise-Scale)
B4: Management group hierarchy (Bosch Platform → Landing Zones → per-OEM subscriptions)
B5: Subscription vending automation and the shared Cloud Hub platform sub
B6: Azure Policy initiatives: CAF baseline + Bosch-custom + per-OEM regulatory; mandatory tagging enforced
B7: Azure Blueprints / Bicep or Terraform module that provisions the entire stack below per subscription
B8: 2. Networking & Connectivity
B9: Hub-spoke topology: hub vNet, Azure Firewall, Azure Bastion
B10: Per spoke vNet (/22) with subnet plan for APIM, AI Foundry private endpoints, AI Search, Cosmos DB, Event Hub, MCP Server compute, Key Vault
B11: Private Endpoints for every PaaS service (AI Foundry, AI Search, Cosmos, Event Hub, Key Vault, Monitor)
B12: Azure Front Door
B13: 3. API Management Gateway (APIM) — Provisioned
... B51: A. Vehicle Profile Mix
B52: Profile | C52: Mix %
B53: Premium | C53: 0.2
B54: Mid-Tier | C54: 0.5
B55: Basic | C55: 0.3
B56: Total | C56: =SUM(C53:C55) -> 1
B58: B. Per-Vehicle Interaction Model
B59: Driver | C59: Premium | D59: Mid-Tier | E59: Basic | F59: Unit | G59: Notes
B60: Active days per year | C60: 330 | D60: 330 | E60: 330 | F60: days | G60: Days vehicle is in active use
B61: Interactions per day | C61: 50 | D61: 35 | E61: 30 | F61: count | G61: Total user-AI exchanges per active day
B62: Cloud offload rate | C62: 0.1 | D62: 0.35 | E62: 0.8 | F62: % | G62: Fraction handled by Azure (vs. edge SLM)
B63: Cost per cloud chain | C63: 0.025 | D63: 0.018 | E63: 0.012 | F63: $ | G63: Avg orchestrator+agent+RAG chain cost (Azure OpenAI)
B64: Telemetry per day | C64: 50 | D64: 15 | E64: 5 | F64: MB | G64: Edge-filtered upload to Event Hub
B66: C. Other Per-Vehicle Annual Costs (USD)
B67: Service Category | C67: Premium | D67: Mid-Tier | E67: Basic | F67: Unit | G67: Notes
B68: Compute & Orchestration | C68: 6 | D68: 10 | E68: 14 | F68: $/yr | G68: AKS, APIM, agent microservices, MCP servers (allocated per active vehicle)
B69: Content Safety + Foundry | C69: 8 | D69: 6 | E69: 5 | F69: $/yr | G69: Azure AI Search index share, Content Safety calls, Foundry tooling overhead
B70: Data & Storage | C70: 18 | D70: 10 | E70: 5 | F70: $/yr | G70: Event Hub ingest, Cosmos DB user context, Fabric/Data Lake retention
B71: Security | C71: 4 | D71: 4 | E71: 4 | F71: $/yr | G71: Entra B2C, WAF, Defender, Key Vault (largely flat per active user)
B72: Monitoring | C72: 3 | D72: 4 | E72: 5 | F72: $/yr | G72: Azure Monitor + App Insights
B73: Networking & Egress | C73: 5 | D73: 4 | E73: 3 | F73: $/yr | G73: Vehicle ↔ cloud data path
B75: D. Stamp Scenarios
B76: Stamp Size | C76: Vehicles | D76: Fixed Cost / yr ($) | G76: Notes
B77: Small | C77: 50000 | D77: 400000 | G77: Pilot / new-region launch
B78: Medium | C78: 250000 | D78: 700000 | G78: Regional steady state
B79: Large | C79: 750000 | D79: 1200000 | G79: Major OEM/region peak
B81: E. Bosch Vehicle Volume Forecast
B82: Year | C82: Total Vehicles | D82: China | E82: Germany | F82: Japan | G82: US
...

Sheet Resource Skills
B3: Assigned Role | C3: Primary Skill | D3: Second skill
B4: {=IFERROR(_xlfn.UNIQUE(_xlfn._xlws.FILTER(('Staffing Plan'!E20:E69),('Staffing Plan'!E20:E69)<>"")),"Resources TBD")} -> Delivery Management Executive1
B5: Program Architect1
B6: Senior Project Manager1
B7: GD Offshore1
B8: GD Offshore2
B9: Senior Domain Solution Architect1
B10: Senior Consultant1
B11: GD Offshore3
B12: Senior Consultant2
B13: Senior Domain Soultion Architect2
B14: Principal Data Scientist1
B15: Data Scientist1
B16: Data Scientist2
... B22: GD Offshore7

Sheet Checklist
B3: 1. Compass One
B4: =TEXT("Completed " & COUNTIF(B7:B20,TRUE) & " of " & COUNTA(B7:B26),"General") -> Completed 0 of 20
B6: Completed | D6: ID | E6: Responsible
B7: FALSE | D7: 1.1 | E7: Architect | F7: Did you submit a consumption(ACR) plan or mark the exception?
B8: FALSE | D8: 1.2 | E8: Pursuit Lead | F8: Are all relevant C1 warnings cleared?
B9: FALSE | D9: 1.3 | E9: Pursuit Lead | F9: Are the "Contracting Customers” and “Supporting Customers” info populated?
B10: FALSE | D10: 1.4 | E10: Pursuit Lead | F10: Are the “Microsoft Contacts” populated correctly? (eg. Signatory should be DME, Relationship Manager=DME, unless PM identified, Primary Delivery=DME, unless PM identified)
B11: FALSE | D11: 1.5 | E11: Pursuit Lead | F11: Are the travel expectations in SOW and in ESWO and C1 consistent (i.e. if there is no travel, SOW should say 'all work is remote', if travel, did you include T&E in C1)
B12: FALSE | D12: 1.6 | E12: Architect / Pursuit Lead | F12: All of the risk assessments completed accurately and completely?
B13: FALSE | D13: 1.8 | E13: Pursuit Lead | F13: Prior to DRM preview provide links for all documents (to be reviewed) in C1 not as actual attachments; After approval by DRM Preview ensure final documents are posted as static documents
B14: FALSE | D14: 1.9 | E14: Pursuit Lead | F14: Add the reviewers to the C1 record (Add DME on the account if it is different from reviewers)
B15: FALSE | D15: 1.1 | E15: Architect | F15: Has ACSM been included where we are delivering solutions with significant change impacts?
B16: FALSE | D16: 1.11 | E16: Architect | F16: If ACSM has not been included, have we added this as a customer responsibility/out of scope and incrased the risk factor?
B17: FALSE | D17: 1.12 | E17: Pursuit Lead | F17: Contract Title contains customer name and project sort title (Ex: "Toyota: D365 Sales Transformation")
B18: FALSE | D18: 1.13 | E18: Pursuit Lead | F18: Prior to DRM, all dates in C1 and executable documents are aligned (ie. C1 "Planned Duration", C1 Financial Packages dates, SOW and ESWO dates)
... B26: FALSE | D26: 1.21 | E26: Pursuit Lead | F26: For deals with ECIF, confirm there is sufficient time to burn ECIF before expiration, allowing for standard staffing timelines (ie. typically 4 weeks)
B28: 2. Solution
B29: =TEXT("Completed " & COUNTIF(B32:B52,TRUE) & " of " & COUNTA(B32:B52),"General") -> Completed 0 of 18
D30: SOW / Overall Deal Shaping
B31: Completed | D31: ID
B32: FALSE | D32: 2.1 | E32: Architect | F32: Does the SOW capture via scope and assumptions what are the top customer Dependencies?
B33: FALSE | D33: 2.2 | E33: Architect | F33: Does the introduction explain what success look like to the customer
B34: FALSE | D34: 2.3 | E34: Architect | F34: Does delivery methodology: LED/Waterfall/other align to customer expectations?
B35: FALSE | D35: 2.4 | E35: Architect | F35: For Deliverables requiring acceptance, confirm they make sense? (e.g. in T&M, generally we dont have signed-off deliverables)
B36: FALSE | D36: 2.5 | E36: Architect | F36: Do you have a timeline showing the initial planned timeline for the Engagement with the multiple work-streams and not the generic timeline?
B37: FALSE | D37: 2.6 | E37: Pursuit Lead | F37: Have you completed RAI and InfoSec reviews, as required?
B38: FALSE | D38: 2.7 | E38: Architect | F38: Did you capture any expected use of OSS (Open Source Software)?
D40: Staffing plan / Timeline
D41: ID
B42: FALSE | D42: 2.6 | E42: Architect | F42: Did you add pre-initiation time (“Week 0”) for PjM & Architect leads with appropriate prep hours?
B43: FALSE | D43: 2.7 | E43: Architect | F43: Did you account for sufficient onboarding requirements and time (i.e. new ISD logo, Customer has significant onboarding requirements into their environment, highly regulated)
B44: FALSE | D44: 2.8 | E44: Architect | F44: If “scrum master” role required, did you specify hours separately from PjM in WBS and C1 and SOW?
B45: FALSE | D45: 2.9 | E45: Architect | F45: Does the staffing plan show a weekly breakdown?
B46: FALSE | D46: 2.10 | E46: Architect | F46: Has the Architect reviewed the skill definitions, and staffing plan (start date and end date, hours/day)?
B47: FALSE | D47: 2.11 | E47: Architect | F47: Has the Architect highlighted any scarce skill on the staffing plan?
B48: FALSE | D48: 2.12 | E48: Pursuit Lead | F48: Have you run the governance calculator and included the results in the WBS spreadsheet?
B49: FALSE | D49: 2.13 | E49: Pursuit Lead | F49: If you are below the minimum governance requirements, have you discussed the reasons with the Area CPMM?
B50: FALSE | D50: 2.14 | E50: Architect | F50: Did you map SOW LED roles to staffing plan and ensure that the SOW roles map to the WBS and map to C1
B51: FALSE | D51: 2.15 | E51: Pursuit Lead | F51: SbD required / not should be validated with Rick Alba and effort included
B52: FALSE | D52: 2.16 | E52: Pursuit Lead | F52: Staffing plan & C1 should be identical at all times
...

Sheet Version
A1: Version | B1: Date | C1: Notes
A2: 0.9 | B2: 45523 | C2: Updated Staffing Plan resourcing description based on( Sola Osunsan) | E2: Training Video: | F2: Staffing Plan Tutorial.mp4
A3: 0.91 | B3: 45527 | C3: Updates Checklist with additional items (Becky Wynne)
A4: 0.92 | B4: 45530 | C4: Added BE Range suggestion (Dean Sesko)
A5: 0.93 | B5: 45572 | C5: Fixed cost calculation (John Gilbert)
A6: 0.94 | B6: 45579 | C6: Fixed formatting
A7: 0.95 | B7: 45583 | C7: Added link to "Compliance Privacy Security Estimator v2.4" workbook. (Sean Leavitt)
A8: 0.96 | B8: 45593 | C8: Added beta for basis of estimation (Joe Newell)
A9: 0.97 | B9: 45614 | C9: Added ability to choose custom %'s for WBS estimates
A10: 0.98 | B10: 45614 | C10: Added responsible column to Checklist (Ravi Thoutireddy)
A11: 0.99 | B11: 45749 | C11: updated SBD to DCPS, changed staffing to table - should make adding columns/rows better
A12: 1 | B12: 45799 | C12: added ability to apply uplift
A13: 1.1 | B13: 45853 | C13: Updated margin for FY26
A14: 1.2 | B14: 45859 | C14: Updated to FY26 Rates

Sheet WBS
F2: 0.1 | G2: 0.6 | H2: 0.1
B3: Estimate Category | C3: Description | D3: Complexity | E3: Dev Sprints or Build (hrs) | F3: Baseline Planning or Envisioning | G3: Testing | H3: Deploy | I3: Total | M3: Category | N3: Estimated Capacity Needed
E4: 10 | F4: =$E4*$F$2 -> 1 | G4: =E4*$G$2 -> 6 | H4: =E4*$H$2 -> 1 | I4: =SUM(E4:H4) -> 18 | M4: {=Helper3!A2:A6} -> Infrastructure | N4: {=IFERROR(SUM(_xlfn._xlws.FILTER($I$4:$I$35,$B$4:$B$35=M4)),0)} -> 0
F5: =$E5*$F$2 -> 0 | G5: =E5*$G$2 -> 0 | H5: =E5*$H$2 -> 0 | I5: =SUM(E5:H5) -> 0 | M5: AI | N5: {=IFERROR(SUM(_xlfn._xlws.FILTER($I$4:$I$35,$B$4:$B$35=M5)),0)} -> 0
F6: =$E6*$F$2 -> 0 | G6: =E6*$G$2 -> 0 | H6: =E6*$H$2 -> 0 | I6: =SUM(E6:H6) -> 0 | M6: Development | N6: {=IFERROR(SUM(_xlfn._xlws.FILTER($I$4:$I$35,$B$4:$B$35=M6)),0)} -> 0
F7: =$E7*$F$2 -> 0 | G7: =E7*$G$2 -> 0 | H7: =E7*$H$2 -> 0 | I7: =SUM(E7:H7) -> 0 | M7: Security | N7: {=IFERROR(SUM(_xlfn._xlws.FILTER($I$4:$I$35,$B$4:$B$35=M7)),0)} -> 0
F8: =$E8*$F$2 -> 0 | G8: =E8*$G$2 -> 0 | H8: =E8*$H$2 -> 0 | I8: =SUM(E8:H8) -> 0 | M8: ASCM | N8: {=IFERROR(SUM(_xlfn._xlws.FILTER($I$4:$I$35,$B$4:$B$35=M8)),0)} -> 0
F9: =$E9*$F$2 -> 0 | G9: =E9*$G$2 -> 0 | H9: =E9*$H$2 -> 0 | I9: =SUM(E9:H9) -> 0
F10: =$E10*$F$2 -> 0 | G10: =E10*$G$2 -> 0 | H10: =E10*$H$2 -> 0 | I10: =SUM(E10:H10) -> 0
F11: =$E11*$F$2 -> 0 | G11: =E11*$G$2 -> 0 | H11: =E11*$H$2 -> 0 | I11: =SUM(E11:H11) -> 0
F12: =$E12*$F$2 -> 0 | G12: =E12*$G$2 -> 0 | H12: =E12*$H$2 -> 0 | I12: =SUM(E12:H12) -> 0
F13: =$E13*$F$2 -> 0 | G13: =E13*$G$2 -> 0 | H13: =E13*$H$2 -> 0 | I13: =SUM(E13:H13) -> 0
F14: =$E14*$F$2 -> 0 | G14: =E14*$G$2 -> 0 | H14: =E14*$H$2 -> 0 | I14: =SUM(E14:H14) -> 0
F15: =$E15*$F$2 -> 0 | G15: =E15*$G$2 -> 0 | H15: =E15*$H$2 -> 0 | I15: =SUM(E15:H15) -> 0
F16: =$E16*$F$2 -> 0 | G16: =E16*$G$2 -> 0 | H16: =E16*$H$2 -> 0 | I16: =SUM(E16:H16) -> 0
F17: =$E17*$F$2 -> 0 | G17: =E17*$G$2 -> 0 | H17: =E17*$H$2 -> 0 | I17: =SUM(E17:H17) -> 0
F18: =$E18*$F$2 -> 0 | G18: =E18*$G$2 -> 0 | H18: =E18*$H$2 -> 0 | I18: =SUM(E18:H18) -> 0
F19: =$E19*$F$2 -> 0 | G19: =E19*$G$2 -> 0 | H19: =E19*$H$2 -> 0 | I19: =SUM(E19:H19) -> 0
F20: =$E20*$F$2 -> 0 | G20: =E20*$G$2 -> 0 | H20: =E20*$H$2 -> 0 | I20: =SUM(E20:H20) -> 0
... F35: =$E35*$F$2 -> 0 | G35: =E35*$G$2 -> 0 | H35: =E35*$H$2 -> 0 | I35: =SUM(E35:H35) -> 0

Sheet CS Staffing Plan UPDATED
A2: Customer | C2: TOTAL | D2: =B7+B11 -> 3402610
A3: MSX-ID
A4: Date | C4: FY Uplift (%)
A5: Price to Win | C5: Week to start FY uplift
A6: =IF($B$5=0,"No Price to Win",IF($B$7>$B$5,"Over Price To Win by ","Under Price To Win by ")) -> No Price to Win | B6: =IF($B$5=0,"-",$B$7-$B$5) -> - | C6: Sold Margin | D6: =SUMPRODUCT(O20:O50,Q20:Q50) -> 0.33650007 | F6: Delivery Capacity (hrs) | G6: Percentage
A7: Revenue | B7: =SUMIF(M20:M50,">0") -> 3242610 | C7: Margin Variance (26.7%) | D7: =D6-0.267 -> 0.069500068 | E7: {=Helper3!A2:A6} -> Infrastructure | F7: {=IFERROR(SUM(_xlfn._xlws.FILTER($R$20:$AT$50,$F$20:$F$50=E7)),0)} -> 0 | G7: =F7/$F12*100 -> 0
A8: Cost | B8: =SUMIF(N21:N51,">0") -> 2099055.4 | C8: Governance (% of hours) | D8: ='CS Staffing Plan UPDATED'!D19 -> 0.15597707 | E8: AI | F8: {=IFERROR(SUM(_xlfn._xlws.FILTER($R$20:$AT$50,$F$20:$F$50=E8)),0)} -> 3591 | G8: =F8/$F12*100 -> 25.660998
C9: Partner Allocation (% of hours) | D9: =SUMIF(G20:I50,"Partner",Q20:Q24) -> 0 | E9: Development | F9: {=IFERROR(SUM(_xlfn._xlws.FILTER($R$20:$AT$50,$F$20:$F$50=E9)),0)} -> 10208 | G9: =F9/$F12*100 -> 72.945548
A10: Risk Reserve | B10: =CONCATENATE(TEXT(B15*B7,"$#,##0" )," at ", TEXT('CS Staffing Plan UPDATED'!B15,"0%")) -> $0 at 0% | C10: Total Hours | D10: =SUM(I20:I50) -> 15872 | E10: Security | F10: {=IFERROR(SUM(_xlfn._xlws.FILTER($R$20:$AT$50,$F$20:$F$50=E10)),0)} -> 195 | G10: =F10/$F12*100 -> 1.3934543
A11: T&E | B11: 160000 | C11: Suggested BE Range | D11: =CONCATENATE("Low: $",CEILING(B7,1000)," - High: $",CEILING((B7*1.2),1000)) -> Low: $3243000 - High: $3892000 | E11: ASCM | F11: {=IFERROR(SUM(_xlfn._xlws.FILTER($R$20:$AT$50,$F$20:$F$50=E11)),0)} -> 0
F12: =SUM(F7:F10) -> 13994
A13: Other Items | C13: Additional Calculators
A14: Travel and Expenses | C14: Governance Calculator: Please run and include a screenshot of the results. | E14: DM Governance Calculator - Power Apps
A15: Risk Reserve (%) | C15: Delivery Compliance, Privacy and Security (DCPS) Estimator: | E15: Compliance Security Estimator
R16: 46197 | S16: =R16+7 -> 46204 | T16: =S16+7 -> 46211 | U16: =T16+7 -> 46218 | V16: =U16+7 -> 46225 | W16: =V16+7 -> 46232 | X16: =W16+7 -> 46239 | Y16: =X16+7 -> 46246 | Z16: =Y16+7 -> 46253 | ... BF16: =BE16+7 -> 46477
R17: Pre-Init | S17: Sprint 0 | U17: Sprint 1 | W17: Sprint 2 | Y17: Sprint 3 | AA17: Sprint 4 | AC17: Sprint 5 | AE17: Sprint 6 | AG17: Sprint 7 | AI17: Sprint 8 | AK17: Sprint 9 | AM17: Sprint 10 | AO17: Sprint 11 | AQ17: Sprint 12
C18: Role | D18: Role Title | E18: Role to Resource Mapping | F18: Role to Functional Area Mapping | G18: Resource Type | H18: Resource Notes and Proposed Individual | I18: Total Hours | J18: List Rate | K18: Bill Rate | L18: Cost Rate | M18: Revenue | N18: Delivery Cost | O18: Sold Margin % | P18: Discount (Premium)% | Q18: Total Allocation % | R18: WK0 | S18: WK1 | T18: WK2 | U18: WK3 | V18: WK4 | W18: WK5 | X18: WK6 | Y18: WK7 | Z18: WK8 | AA18: WK9 | AB18: WK10 | AC18: WK11 | AD18: WK12 | AE18: WK13 | AF18: WK14 | AG18: WK15 | AH18: WK16 | AI18: WK17 | AJ18: WK18 | AK18: WK19 | AL18: WK20 | AM18: WK21 | AN18: WK22 | AO18: WK23 | AP18: WK24 | AQ18: WK25 | AR18: WK26 | AS18: WK27 | AT18: WK28 | AU18: WK29 | AV18: WK30 | AW18: WK31 | AX18: WK32 | AY18: WK33 | AZ18: WK34 | BA18: WK35 | BB18: WK36 | BC18: WK37 | BD18: WK38 | BE18: WK39 | BF18: WK40
C19: Governance Team | D19: =SUM(Q20:Q24) -> 0.15597707 | R19: 46209 | S19: 46216 | T19: 46223 | U19: 46230 | V19: 46237 | W19: 46244 | X19: 46251 | Y19: 46258 | Z19: 46265 | AA19: 46272 | AB19: 46279 | AC19: 46286 | AD19: 46293 | AE19: 46300 | AF19: 46307 | AG19: 46314 | AH19: 46321 | AI19: 46328 | AJ19: 46335 | AK19: 46342 | AL19: 46349 | AM19: 46356 | AN19: 46363 | AO19: 46370 | AP19: 46377 | AQ19: 46384 | AR19: 46391
C20: DME | D20: Delivery Management Executive | E20: Delivery Management Executive1 | G20: US | I20: =SUM(R20:AT20) -> 110 | J20: 478.4 | K20: =J20 -> 478.4 | L20: 476.51 | M20: {=IF(Table13[[#This Row],[Total Hours]]=0,"-",SUMPRODUCT(Table13[[#This Row],[WK0]:[WK28]], Table13[[#This Row],[Bill Rate]]*IF(COLUMN(Table13[[#This Row],[WK0]:[WK28]])-COLUMN(Table13[[#This Row],[WK0]])>=$D$5, 1+$D$4, 1)))} -> 52624 | N20: {=IF(Table13[[#This Row],[Total Hours]]=0,"-",SUMPRODUCT(Table13[[#This Row],[WK0]:[WK28]], Table13[[#This Row],[Cost Rate]]*IF(COLUMN(Table13[[#This Row],[WK0]:[WK28]])-COLUMN(Table13[[#This Row],[WK0]])>=$D$5, 1+$D$4, 1)))} -> 52416.1 | O20: =IFERROR((M20-N20)/M20,"-") -> 0.0039506689 | P20: =IFERROR((J20-K20)/J20,0) -> 0 | Q20: =IFERROR(M20/$B$7,0) -> 0.016228902 | R20: 6 | S20: 4 | T20: 4 | U20: 4 | V20: 4 | W20: 4 | X20: 4 | Y20: 4 | Z20: 4 | AA20: 4 | AB20: 4 | AC20: 4 | AD20: 4 | AE20: 4 | AF20: 4 | AG20: 4 | AH20: 4 | AI20: 4 | AJ20: 4 | AK20: 4 | AL20: 4 | AM20: 4 | AN20: 4 | AO20: 4 | AP20: 4 | AQ20: 4 | AR20: 4
C21: Program Architect | D21: Program Architect | E21: Program Architect1 | F21: AI | G21: US | I21: =SUM(R21:AT21) -> 240 | J21: 520 | K21: =J21 -> 520 | L21: 477.33 | M21: {=IF(Table13[[#This Row],[Total Hours]]=0,"-",SUMPRODUCT(Table13[[#This Row],[WK0]:[WK28]], Table13[[#This Row],[Bill Rate]]*IF(COLUMN(Table13[[#This Row],[WK0]:[WK28]])-COLUMN(Table13[[#This Row],[WK0]])>=$D$5, 1+$D$4, 1)))} -> 124800 | N21: {=IF(Table13[[#This Row],[Total Hours]]=0,"-",SUMPRODUCT(Table13[[#This Row],[WK0]:[WK28]], Table13[[#This Row],[Cost Rate]]*IF(COLUMN(Table13[[#This Row],[WK0]:[WK28]])-COLUMN(Table13[[#This Row],[WK0]])>=$D$5, 1+$D$4, 1)))} -> 114559.2 | O21: =IFERROR((M21-N21)/M21,"-") -> 0.082057692 | P21: =IFERROR((J21-K21)/J21,0) -> 0 | Q21: =IFERROR(M21/$B$7,0) -> 0.038487515 | R21: 8 | S21: 16 | T21: 16 | U21: 16 | V21: 8 | W21: 8 | X21: 8 | Y21: 8 | Z21: 8 | AA21: 8 | AB21: 8 | AC21: 8 | AD21: 8 | AE21: 8 | AF21: 8 | AG21: 8 | AH21: 8 | AI21: 8 | AJ21: 8 | AK21: 8 | AL21: 8 | AM21: 8 | AN21: 8 | AO21: 8 | AP21: 8 | AQ21: 8 | AR21: 8
C22: Project Manager | D22: Senior Project Manager | E22: Senior Project Manager1 | G22: US | I22: =SUM(R22:AT22) -> 720 | J22: 384.8 | K22: =J22 -> 384.8 | L22: 267.41 | M22: {=IF(Table13[[#This Row],[Total Hours]]=0,"-",SUMPRODUCT(Table13[[#This Row],[WK0]:[WK28]], Table13[[#This Row],[Bill Rate]]*IF(COLUMN(Table13[[#This Row],[WK0]:[WK28]])-COLUMN(Table13[[#This Row],[WK0]])>=$D$5, 1+$D$4, 1)))} -> 277056 | N22: {=IF(Table13[[#This Row],[Total Hours]]=0,"-",SUMPRODUCT(Table13[[#This Row],[WK0]:[WK28]], Table13[[#This Row],[Cost Rate]]*IF(COLUMN(Table13[[#This Row],[WK0]:[WK28]])-COLUMN(Table13[[#This Row],[WK0]])>=$D$5, 1+$D$4, 1)))} -> 192535.2 | O22: =IFERROR((M22-N22)/M22,"-") -> 0.30506757 | P22: =IFERROR((J22-K22)/J22,0) -> 0 | Q22: =IFERROR(M22/$B$7,0) -> 0.085442283 | R22: 16 | S22: 32 | T22: 32 | U22: 32 | V22: 32 | W22: 32 | X22: 32 | Y22: 32 | Z22: 32 | AA22: 32 | AB22: 32 | AC22: 24 | AD22: 24 | AE22: 24 | AF22: 24 | AG22: 24 | AH22: 24 | AI22: 24 | AJ22: 24 | AK22: 24 | AL22: 24 | AM22: 24 | AN22: 24 | AO22: 24 | AP22: 24 | AQ22: 24 | AR22: 24
C23: Scrum Master / Project Manager | D23: GD Offshore | E23: GD Offshore1 | G23: GDC | I23: =SUM(R23:AT23) -> 480 | J23: 93.6 | K23: =J23 -> 93.6 | L23: 55.77 | M23: {=IF(Table13[[#This Row],[Total Hours]]=0,"-",SUMPRODUCT(Table13[[#This Row],[WK0]:[WK28]], Table13[[#This Row],[Bill Rate]]*IF(COLUMN(Table13[[#This Row],[WK0]:[WK28]])-COLUMN(Table13[[#This Row],[WK0]])>=$D$5, 1+$D$4, 1)))} -> 44928 | N23: {=IF(Table13[[#This Row],[Total Hours]]=0,"-",SUMPRODUCT(Table13[[#This Row],[WK0]:[WK28]], Table13[[#This Row],[Cost Rate]]*IF(COLUMN(Table13[[#This Row],[WK0]:[WK28]])-COLUMN(Table13[[#This Row],[WK0]])>=$D$5, 1+$D$4, 1)))} -> 26769.6 | O23: =IFERROR((M23-N23)/M23,"-") -> 0.40416667 | P23: =IFERROR((J23-K23)/J23,0) -> 0 | Q23: =IFERROR(M23/$B$7,0) -> 0.013855505 | R23: 8 | S23: 24 | T23: 24 | U23: 24 | V23: 24 | W23: 24 | X23: 24 | Y23: 24 | Z23: 16 | AA23: 16 | AB23: 16 | AC23: 16 | AD23: 16 | AE23: 16 | AF23: 16 | AG23: 16 | AH23: 16 | AI23: 16 | AJ23: 16 | AK23: 16 | AL23: 16 | AM23: 16 | AN23: 16 | AO23: 16 | AP23: 16 | AQ23: 16 | AR23: 16
C24: TQA | D24: GD Offshore | E24: GD Offshore2 | G24: GDC | I24: =SUM(R24:AT24) -> 68 | J24: 93.6 | K24: =J24 -> 93.6 | L24: 55.77 | M24: {=IF(Table13[[#This Row],[Total Hours]]=0,"-",SUMPRODUCT(Table13[[#This Row],[WK0]:[WK28]], Table13[[#This Row],[Bill Rate]]*IF(COLUMN(Table13[[#This Row],[WK0]:[WK28]])-COLUMN(Table13[[#This Row],[WK0]])>=$D$5, 1+$D$4, 1)))} -> 6364.8 | N24: {=IF(Table13[[#This Row],[Total Hours]]=0,"-",SUMPRODUCT(Table13[[#This Row],[WK0]:[WK28]], Table13[[#This Row],[Cost Rate]]*IF(COLUMN(Table13[[#This Row],[WK0]:[WK28]])-COLUMN(Table13[[#This Row],[WK0]])>=$D$5, 1+$D$4, 1)))} -> 3792.36 | O24: =IFERROR((M24-N24)/M24,"-") -> 0.40416667 | P24: =IFERROR((J24-K24)/J24,0) -> 0 | Q24: =IFERROR(M24/$B$7,0) -> 0.0019628632 | S24: 2 | T24: 2 | U24: 2 | V24: 2 | W24: 2 | X24: 2 | Y24: 2 | Z24: 2 | AA24: 2 | AB24: 2 | AC24: 3 | AD24: 3 | AE24: 3 | AF24: 3 | AG24: 3 | AH24: 3 | AI24: 3 | AJ24: 3 | AK24: 3 | AL24: 3 | AM24: 3 | AN24: 3 | AO24: 3 | AP24: 3 | AQ24: 3 | AR24: 3
C25: In Vehicle (Edge) - Agentic Solution -AI SLM, Model Tuning | D25: =SUM(Q26:Q41) -> 0.83445397
C26: Prin Data Scientist - Charlie Gu | D26: Principal Data Scientist | E26: Principal Data Scientist1 | F26: AI | G26: Singapore | H26: Language Model training and fine tunning | I26: =SUM(R26:AT26) -> 903 | J26: 500 | K26: =J26 -> 500 | L26: 361.54 | M26: =IF(I26=0,"-",K26*I26) -> 451500 | N26: =IF(I26=0,"-",L26*I26) -> 326470.62 | O26: =IFERROR((M26-N26)/M26,"-") -> 0.27692 | P26: =IFERROR((J26-K26)/J26,0) -> 0 | Q26: =IFERROR(M26/$B$7,0) -> 0.13923969 | R26: 24 | S26: 40 | T26: 40 | U26: 40 | V26: 40 | W26: 40 | X26: 39 | Y26: 32 | Z26: 32 | AA26: 32 | AB26: 32 | AC26: 32 | AD26: 32 | AE26: 32 | AF26: 32 | AG26: 32 | AH26: 32 | AI26: 32 | AJ26: 32 | AK26: 32 | AL26: 32 | AM26: 32 | AN26: 32 | AO26: 32 | AP26: 32 | AQ26: 32 | AR26: 32
C27: Sr. Data Scientist Zachary Hou | D27: Data Scientist | E27: Data Scientist1 | F27: AI | G27: Indian | H27: Speech To Text Model training and fine tunning | I27: =SUM(R27:AT27) -> 384 | J27: 416 | K27: =J27 -> 416 | L27: 375.05 | M27: =IF(I27=0,"-",K27*I27) -> 159744 | N27: =IF(I27=0,"-",L27*I27) -> 144019.2 | O27: =IFERROR((M27-N27)/M27,"-") -> 0.0984375 | P27: =IFERROR((J27-K27)/J27,0) -> 0 | Q27: =IFERROR(M27/$B$7,0) -> 0.049264019 | AE27: 32 | AF27: 32 | AG27: 32 | AH27: 32 | AI27: 32 | AJ27: 32 | AK27: 32 | AL27: 32 | AM27: 32 | AN27: 32 | AO27: 32 | AP27: 32
C28: Sr. Data Scientist Yoi Xiang | D28: Data Scientist | E28: Data Scientist2 | F28: AI | G28: ANZ | H28: Speech To Speech Model training and fine tunning | I28: =SUM(R28:AT28) -> 840 | J28: 400 | K28: =J28 -> 400 | L28: 312.19 | M28: =IF(I28=0,"-",K28*I28) -> 336000 | N28: =IF(I28=0,"-",L28*I28) -> 262239.6 | O28: =IFERROR((M28-N28)/M28,"-") -> 0.219525 | P28: =IFERROR((J28-K28)/J28,0) -> 0 | Q28: =IFERROR(M28/$B$7,0) -> 0.10362023 | R28: 8 | S28: 40 | T28: 40 | U28: 40 | V28: 40 | W28: 32 | X28: 32 | Y28: 32 | Z28: 32 | AA28: 32 | AB28: 32 | AC28: 32 | AD28: 32 | AE28: 32 | AF28: 32 | AG28: 32 | AH28: 32 | AI28: 32 | AJ28: 32 | AK28: 32 | AL28: 32 | AM28: 32 | AN28: 32 | AO28: 24 | AP28: 24 | AQ28: 24 | AR28: 24
C29: Sr. Data Scientist Murumalla Krishnakant Achary | D29: Data Scientist | E29: Data Scientist3 | F29: AI | G29: China | H29: Text to Speech Model training and fine tuning | I29: =SUM(R29:AT29) -> 840 | J29: 416 | K29: =J29 -> 416 | L29: 312.25 | M29: =IF(I29=0,"-",K29*I29) -> 349440 | N29: =IF(I29=0,"-",L29*I29) -> 262290 | O29: =IFERROR((M29-N29)/M29,"-") -> 0.24939904 | P29: =IFERROR((J29-K29)/J29,0) -> 0 | Q29: =IFERROR(M29/$B$7,0) -> 0.10776504 | R29: 8 | S29: 40 | T29: 40 | U29: 40 | V29: 40 | W29: 32 | X29: 32 | Y29: 32 | Z29: 32 | AA29: 32 | AB29: 32 | AC29: 32 | AD29: 32 | AE29: 32 | AF29: 32 | AG29: 32 | AH29: 32 | AI29: 32 | AJ29: 32 | AK29: 32 | AL29: 32 | AM29: 32 | AN29: 32 | AO29: 24 | AP29: 24 | AQ29: 24 | AR29: 24
C30: Sr. Data Scientist | D30: Data Scientist | E30: Data Scientist4 | F30: AI | G30: US | H30: Wakeup word/VAD training and fine tuning | I30: =SUM(R30:AT30) -> 384 | J30: =IFERROR(VLOOKUP(D30,Rates!$A$2:$C$26,3,TRUE),"-") -> 400 | K30: =J30 -> 400 | L30: 128.18 | M30: =IF(I30=0,"-",K30*I30) -> 153600 | N30: =IF(I30=0,"-",L30*I30) -> 49221.12 | O30: =IFERROR((M30-N30)/M30,"-") -> 0.67955 | P30: =IFERROR((J30-K30)/J30,0) -> 0 | Q30: =IFERROR(M30/$B$7,0) -> 0.047369249 | AE30: 32 | AF30: 32 | AG30: 32 | AH30: 32 | AI30: 32 | AJ30: 32 | AK30: 32 | AL30: 32 | AM30: 32 | AN30: 32 | AO30: 32 | AP30: 32
C31: Sr. Consultant Yifeng Li | D31: Senior Consultant | E31: Senior Consultant2 | F31: Development | G31: China | H31: Device Integration, Testing Framework | I31: =SUM(R31:AT31) -> 840 | J31: =IFERROR(VLOOKUP(D31,Rates!$A$2:$C$26,3,TRUE),"-") -> 365 | K31: =J31 -> 365 | L31: 137.7 | M31: =IF(I31=0,"-",K31*I31) -> 306600 | N31: =IF(I31=0,"-",L31*I31) -> 115668 | O31: =IFERROR((M31-N31)/M31,"-") -> 0.62273973 | P31: =IFERROR((J31-K31)/J31,0) -> 0 | Q31: =IFERROR(M31/$B$7,0) -> 0.094553462 | S31: 40 | T31: 40 | U31: 40 | V31: 40 | W31: 40 | X31: 32 | Y31: 32 | Z31: 32 | AA31: 32 | AB31: 32 | AC31: 32 | AD31: 32 | AE31: 32 | AF31: 32 | AG31: 32 | AH31: 32 | AI31: 32 | AJ31: 32 | AK31: 32 | AL31: 32 | AM31: 32 | AN31: 32 | AO31: 24 | AP31: 24 | AQ31: 24 | AR31: 24
C32: Consultant / Developer | D32: GD Offshore | E32: GD Offshore4 | F32: Development | G32: GDC | H32: Developer | I32: =SUM(R32:AT32) -> 1040 | J32: 93.6 | K32: =J32 -> 93.6 | L32: 55.77 | M32: =IF(I32=0,"-",K32*I32) -> 97344 | N32: =IF(I32=0,"-",L32*I32) -> 58000.8 | O32: =IFERROR((M32-N32)/M32,"-") -> 0.40416667 | P32: =IFERROR((J32-K32)/J32,0) -> 0 | Q32: =IFERROR(M32/$B$7,0) -> 0.030020261 | S32: 40 | T32: 40 | U32: 40 | V32: 40 | W32: 40 | X32: 40 | Y32: 40 | Z32: 40 | AA32: 40 | AB32: 40 | AC32: 40 | AD32: 40 | AE32: 40 | AF32: 40 | AG32: 40 | AH32: 40 | AI32: 40 | AJ32: 40 | AK32: 40 | AL32: 40 | AM32: 40 | AN32: 40 | AO32: 40 | AP32: 40 | AQ32: 40 | AR32: 40
C33: Consultant / Developer | D33: GD Offshore | E33: GD Offshore5 | F33: Development | G33: GDC | H33: Tester | I33: =SUM(R33:AT33) -> 1040 | J33: 93.6 | K33: =J33 -> 93.6 | L33: 55.77 | M33: =IF(I33=0,"-",K33*I33) -> 97344 | N33: =IF(I33=0,"-",L33*I33) -> 58000.8 | O33: =IFERROR((M33-N33)/M33,"-") -> 0.40416667 | P33: =IFERROR((J33-K33)/J33,0) -> 0 | Q33: =IFERROR(M33/$B$7,0) -> 0.030020261 | S33: 40 | T33: 40 | U33: 40 | V33: 40 | W33: 40 | X33: 40 | Y33: 40 | Z33: 40 | AA33: 40 | AB33: 40 | AC33: 40 | AD33: 40 | AE33: 40 | AF33: 40 | AG33: 40 | AH33: 40 | AI33: 40 | AJ33: 40 | AK33: 40 | AL33: 40 | AM33: 40 | AN33: 40 | AO33: 40 | AP33: 40 | AQ33: 40 | AR33: 40
C34: Consultant / Developer | D34: GD Offshore | E34: GD Offshore6 | F34: Development | G34: GDC | H34: Training Data | I34: =SUM(R34:AT34) -> 1040 | J34: 94.6 | K34: =J34 -> 94.6 | L34: 56.77 | M34: =IF(I34=0,"-",K34*I34) -> 98384 | N34: =IF(I34=0,"-",L34*I34) -> 59040.8 | O34: =IFERROR((M34-N34)/M34,"-") -> 0.39989429 | P34: =IFERROR((J34-K34)/J34,0) -> 0 | Q34: =IFERROR(M34/$B$7,0) -> 0.030340991 | S34: 40 | T34: 40 | U34: 40 | V34: 40 | W34: 40 | X34: 40 | Y34: 40 | Z34: 40 | AA34: 40 | AB34: 40 | AC34: 40 | AD34: 40 | AE34: 40 | AF34: 40 | AG34: 40 | AH34: 40 | AI34: 40 | AJ34: 40 | AK34: 40 | AL34: 40 | AM34: 40 | AN34: 40 | AO34: 40 | AP34: 40 | AQ34: 40 | AR34: 40
C35: Consultant / Developer | D35: GD Offshore | E35: GD Offshore7 | F35: Development | G35: GDC | H35: Training Data | I35: =SUM(R35:AT35) -> 1040 | J35: 95.6 | K35: =J35 -> 95.6 | L35: 57.77 | M35: =IF(I35=0,"-",K35*I35) -> 99424 | N35: =IF(I35=0,"-",L35*I35) -> 60080.8 | O35: =IFERROR((M35-N35)/M35,"-") -> 0.3957113 | P35: =IFERROR((J35-K35)/J35,0) -> 0 | Q35: =IFERROR(M35/$B$7,0) -> 0.03066172 | S35: 40 | T35: 40 | U35: 40 | V35: 40 | W35: 40 | X35: 40 | Y35: 40 | Z35: 40 | AA35: 40 | AB35: 40 | AC35: 40 | AD35: 40 | AE35: 40 | AF35: 40 | AG35: 40 | AH35: 40 | AI35: 40 | AJ35: 40 | AK35: 40 | AL35: 40 | AM35: 40 | AN35: 40 | AO35: 40 | AP35: 40 | AQ35: 40 | AR35: 40
